Workbook

Sheet Method
B2: Clean LOD Pipeline: Data, Bands, and A2 Precursor Index
B4: Purpose
B5: This workbook documents the clean length-of-day (LOD) dataset for the LOD-ENSO study, rebuilt after correction of
B6: a computational error that had inflated the 0.5-1 yr band amplitude by roughly 2.7x. Everything here is re-derivable.
B8: Source data
B9: Raw daily LOD: IERS EOP 20 C04 series, file EOP_20u24_C04_...1962-now26may.txt, LOD column (s), converted to ms.
B10: Daily values averaged to monthly means (months with < 20 valid days dropped). Band window: 1963 to 2022 (720 months).
B11: The same monthly series extended to 2026-04 is used only to compute the 2026 forecast value of A2.
B13: Processing pipeline
B14: Step 1. Monthly-mean LOD (ms); subtract the series mean.
B15: Step 2. Remove six zonal-tidal / seasonal harmonics by least-squares sine+cosine fit at periods
B16: 1.000 yr (Sa), 0.500 yr (Ssa), 0.333 yr, 0.250 yr, 18.613 yr, 9.307 yr -> DeTided_DeSeasonalized_ms.
... B31: Corrupted_vs_Clean what the correction changed, side by side.

Sheet Band_Summary
A1: Band | B1: Period range | C1: Column | D1: Sigma (ms) | E1: Variance share (%)
A2: (i) High-pass | B2: 0 to 0.5 yr | C2: F | D2: =STDEV(Band_TimeSeries!F2:F721) -> 0.086139757 | E2: =VAR(Band_TimeSeries!F2:F721)/VAR(Band_TimeSeries!E2:E721)*100 -> 1.0516899
A3: (ii) Sub-annual | B3: 0.5 to 1 yr | C3: G | D3: =STDEV(Band_TimeSeries!G2:G721) -> 0.063635315 | E3: =VAR(Band_TimeSeries!G2:G721)/VAR(Band_TimeSeries!E2:E721)*100 -> 0.57395364
A4: (iii) Transition | B4: 1 to 1.5 yr | C4: H | D4: =STDEV(Band_TimeSeries!H2:H721) -> 0.04349841 | E4: =VAR(Band_TimeSeries!H2:H721)/VAR(Band_TimeSeries!E2:E721)*100 -> 0.26818049
A5: (iv) Quasi-biennial | B5: 1.5 to 2 yr | C5: I | D5: =STDEV(Band_TimeSeries!I2:I721) -> 0.042234401 | E5: =VAR(Band_TimeSeries!I2:I721)/VAR(Band_TimeSeries!E2:E721)*100 -> 0.25282097
A6: (v) ENSO-band | B6: 2 to 10 yr | C6: J | D6: =STDEV(Band_TimeSeries!J2:J721) -> 0.15073984 | E6: =VAR(Band_TimeSeries!J2:J721)/VAR(Band_TimeSeries!E2:E721)*100 -> 3.2205981
A7: Secular (residual) | B7: > 10 yr | C7: K | D7: =STDEV(Band_TimeSeries!K2:K721) -> 0.80252483 | E7: =VAR(Band_TimeSeries!K2:K721)/VAR(Band_TimeSeries!E2:E721)*100 -> 91.284569
A8: De-tided total | C8: E | D8: =STDEV(Band_TimeSeries!E2:E721) -> 0.8399623 | E8: 100
A10: Live formulas over the 720 monthly values. Clean 0.5-1 yr sigma = 0.064 ms.

Sheet Band_TimeSeries
A1: Year | B1: Month | C1: Raw_LOD_ms | D1: Tidal_seasonal_fit_ms | E1: DeTided_DeSeasonalized_ms | F1: B0_0.5yr | G1: B0.5_1yr | H1: B1_1.5yr | I1: B1.5_2yr | J1: B2_10yr | K1: Secular_gt10yr
A2: 1963 | B2: 1 | C2: 1.0492581 | D2: 1.336327 | E2: -0.28706895 | F2: -0.038599618 | G2: -0.08942597 | H2: -0.061550071 | I2: -0.071519907 | J2: -0.3484361 | K2: 0.32246272
A3: 1963 | B3: 2 | C3: 1.2212857 | D3: 1.4666109 | E3: -0.24532522 | F3: -0.075213559 | G3: -0.076535533 | H3: -0.059878782 | I3: -0.061562114 | J3: -0.31033953 | K3: 0.3382043
A4: 1963 | B4: 3 | C4: 1.6346452 | D4: 1.5969852 | E4: 0.037659998 | F4: 0.061056381 | G4: -0.016653911 | H4: -0.047667802 | I4: -0.045679337 | J4: -0.26660441 | K4: 0.35320908
A5: 1963 | B5: 4 | C5: 1.8191333 | D5: 1.6520875 | E5: 0.16704581 | F5: 0.019816211 | G5: 0.049100158 | H5: -0.027556021 | I5: -0.025381566 | J5: -0.21849445 | K5: 0.36956149
A6: 1963 | B6: 5 | C6: 1.6342903 | D6: 1.3927654 | E6: 0.24152495 | F6: -0.049352843 | G6: 0.077009406 | H6: -0.0036256949 | I6: -0.002626028 | J6: -0.16744892 | K6: 0.38756903
A7: 1963 | B7: 6 | C7: 1.2920333 | D7: 0.80076242 | E7: 0.49127091 | F7: 0.10582748 | G7: 0.05257001 | H7: 0.019491224 | I7: 0.020376204 | J7: -0.11500825 | K7: 0.40801424
A8: 1963 | B8: 7 | C8: 0.81625806 | D8: 0.45190724 | E8: 0.36435082 | F8: -0.082628618 | G8: -0.0012096573 | H8: 0.037593977 | I8: 0.041381215 | J8: -0.062733154 | K8: 0.43194706
A9: 1963 | B9: 8 | C9: 1.1246774 | D9: 0.63046412 | E9: 0.4942133 | F9: -0.013852064 | G9: -0.044092853 | H9: 0.04775801 | I9: 0.058338243 | J9: -0.012123073 | K9: 0.45818504
A10: 1963 | B10: 9 | C10: 1.5836333 | D10: 1.0275139 | E10: 0.55611942 | F10: -0.030999567 | G10: -0.049358921 | H10: 0.048857882 | I10: 0.069597294 | J10: 0.035460528 | K10: 0.48256221
A11: 1963 | B11: 10 | C11: 2.1366452 | D11: 1.3468478 | E11: 0.78979733 | F11: 0.11348686 | G11: -0.020372313 | H11: 0.041662743 | I11: 0.074076734 | J11: 0.078860879 | K11: 0.50208243
A12: 1963 | B12: 11 | C12: 2.119 | D12: 1.3915497 | E12: 0.72745029 | F12: -0.026287899 | G12: 0.017351331 | H12: 0.028503676 | I12: 0.07137322 | J12: 0.11717846 | K12: 0.5193315
A13: 1963 | B13: 12 | C13: 1.8727097 | D13: 1.2126675 | E13: 0.66004216 | F13: -0.1417905 | G13: 0.038164635 | H13: 0.012614466 | I13: 0.061802281 | J13: 0.14980625 | K13: 0.53944502
... A721: 2022 | B721: 12 | C721: 0.0089 | D721: 1.2325296 | E721: -1.2236296 | F721: -0.073518004 | G721: 0.021589355 | H721: 0.060870826 | I721: 0.0089942046 | J721: -0.033020898 | K721: -1.208545

Sheet A2_Index
A1: Event Year | B1: Band 0.5-1yr Y-1 Mar (ms) | C1: Band 0.5-1yr Y-1 Jul (ms) | D1: A2 = Mar - Jul (ms) | E1: ENSO type
A2: 1964 | B2: =SUMIFS(Band_TimeSeries!$G$2:$G$721,Band_TimeSeries!$A$2:$A$721,1963,Band_TimeSeries!$B$2:$B$721,3) -> -0.016653911 | C2: =SUMIFS(Band_TimeSeries!$G$2:$G$721,Band_TimeSeries!$A$2:$A$721,1963,Band_TimeSeries!$B$2:$B$721,7) -> -0.0012096573 | D2: =B2-C2 -> -0.015444253 | E2: La Nina
A3: 1965 | B3: =SUMIFS(Band_TimeSeries!$G$2:$G$721,Band_TimeSeries!$A$2:$A$721,1964,Band_TimeSeries!$B$2:$B$721,3) -> -0.014687572 | C3: =SUMIFS(Band_TimeSeries!$G$2:$G$721,Band_TimeSeries!$A$2:$A$721,1964,Band_TimeSeries!$B$2:$B$721,7) -> -0.00924806 | D3: =B3-C3 -> -0.0054395118 | E3: El Nino
A4: 1966 | B4: =SUMIFS(Band_TimeSeries!$G$2:$G$721,Band_TimeSeries!$A$2:$A$721,1965,Band_TimeSeries!$B$2:$B$721,3) -> -0.054856238 | C4: =SUMIFS(Band_TimeSeries!$G$2:$G$721,Band_TimeSeries!$A$2:$A$721,1965,Band_TimeSeries!$B$2:$B$721,7) -> 0.05407827 | D4: =B4-C4 -> -0.10893451 | E4: neutral
A5: 1967 | B5: =SUMIFS(Band_TimeSeries!$G$2:$G$721,Band_TimeSeries!$A$2:$A$721,1966,Band_TimeSeries!$B$2:$B$721,3) -> 0.015294321 | C5: =SUMIFS(Band_TimeSeries!$G$2:$G$721,Band_TimeSeries!$A$2:$A$721,1966,Band_TimeSeries!$B$2:$B$721,7) -> -0.001347463 | D5: =B5-C5 -> 0.016641784 | E5: La Nina
A6: 1968 | B6: =SUMIFS(Band_TimeSeries!$G$2:$G$721,Band_TimeSeries!$A$2:$A$721,1967,Band_TimeSeries!$B$2:$B$721,3) -> 0.00062329981 | C6: =SUMIFS(Band_TimeSeries!$G$2:$G$721,Band_TimeSeries!$A$2:$A$721,1967,Band_TimeSeries!$B$2:$B$721,7) -> -0.01134746 | D6: =B6-C6 -> 0.01197076 | E6: neutral
A7: 1969 | B7: =SUMIFS(Band_TimeSeries!$G$2:$G$721,Band_TimeSeries!$A$2:$A$721,1968,Band_TimeSeries!$B$2:$B$721,3) -> -0.088153423 | C7: =SUMIFS(Band_TimeSeries!$G$2:$G$721,Band_TimeSeries!$A$2:$A$721,1968,Band_TimeSeries!$B$2:$B$721,7) -> 0.12323354 | D7: =B7-C7 -> -0.21138697 | E7: neutral
A8: 1970 | B8: =SUMIFS(Band_TimeSeries!$G$2:$G$721,Band_TimeSeries!$A$2:$A$721,1969,Band_TimeSeries!$B$2:$B$721,3) -> 0.083956085 | C8: =SUMIFS(Band_TimeSeries!$G$2:$G$721,Band_TimeSeries!$A$2:$A$721,1969,Band_TimeSeries!$B$2:$B$721,7) -> -0.017239318 | D8: =B8-C8 -> 0.1011954 | E8: La Nina
A9: 1971 | B9: =SUMIFS(Band_TimeSeries!$G$2:$G$721,Band_TimeSeries!$A$2:$A$721,1970,Band_TimeSeries!$B$2:$B$721,3) -> 0.083694682 | C9: =SUMIFS(Band_TimeSeries!$G$2:$G$721,Band_TimeSeries!$A$2:$A$721,1970,Band_TimeSeries!$B$2:$B$721,7) -> -0.1089186 | D9: =B9-C9 -> 0.19261328 | E9: La Nina
A10: 1972 | B10: =SUMIFS(Band_TimeSeries!$G$2:$G$721,Band_TimeSeries!$A$2:$A$721,1971,Band_TimeSeries!$B$2:$B$721,3) -> -0.10307465 | C10: =SUMIFS(Band_TimeSeries!$G$2:$G$721,Band_TimeSeries!$A$2:$A$721,1971,Band_TimeSeries!$B$2:$B$721,7) -> 0.053984714 | D10: =B10-C10 -> -0.15705937 | E10: El Nino
A11: 1973 | B11: =SUMIFS(Band_TimeSeries!$G$2:$G$721,Band_TimeSeries!$A$2:$A$721,1972,Band_TimeSeries!$B$2:$B$721,3) -> -0.049477208 | C11: =SUMIFS(Band_TimeSeries!$G$2:$G$721,Band_TimeSeries!$A$2:$A$721,1972,Band_TimeSeries!$B$2:$B$721,7) -> 0.059512212 | D11: =B11-C11 -> -0.10898942 | E11: La Nina
A12: 1974 | B12: =SUMIFS(Band_TimeSeries!$G$2:$G$721,Band_TimeSeries!$A$2:$A$721,1973,Band_TimeSeries!$B$2:$B$721,3) -> -0.0012656277 | C12: =SUMIFS(Band_TimeSeries!$G$2:$G$721,Band_TimeSeries!$A$2:$A$721,1973,Band_TimeSeries!$B$2:$B$721,7) -> 0.019913414 | D12: =B12-C12 -> -0.021179042 | E12: neutral
A13: 1975 | B13: =SUMIFS(Band_TimeSeries!$G$2:$G$721,Band_TimeSeries!$A$2:$A$721,1974,Band_TimeSeries!$B$2:$B$721,3) -> 0.0067503574 | C13: =SUMIFS(Band_TimeSeries!$G$2:$G$721,Band_TimeSeries!$A$2:$A$721,1974,Band_TimeSeries!$B$2:$B$721,7) -> -0.0074605232 | D13: =B13-C13 -> 0.014210881 | E13: La Nina
A14: 1976 | B14: =SUMIFS(Band_TimeSeries!$G$2:$G$721,Band_TimeSeries!$A$2:$A$721,1975,Band_TimeSeries!$B$2:$B$721,3) -> 0.0030024185 | C14: =SUMIFS(Band_TimeSeries!$G$2:$G$721,Band_TimeSeries!$A$2:$A$721,1975,Band_TimeSeries!$B$2:$B$721,7) -> -0.02196275 | D14: =B14-C14 -> 0.024965169 | E14: El Nino
A15: 1977 | B15: =SUMIFS(Band_TimeSeries!$G$2:$G$721,Band_TimeSeries!$A$2:$A$721,1976,Band_TimeSeries!$B$2:$B$721,3) -> -0.026090358 | C15: =SUMIFS(Band_TimeSeries!$G$2:$G$721,Band_TimeSeries!$A$2:$A$721,1976,Band_TimeSeries!$B$2:$B$721,7) -> 0.019894932 | D15: =B15-C15 -> -0.04598529 | E15: neutral
A16: 1978 | B16: =SUMIFS(Band_TimeSeries!$G$2:$G$721,Band_TimeSeries!$A$2:$A$721,1977,Band_TimeSeries!$B$2:$B$721,3) -> 0.043810268 | C16: =SUMIFS(Band_TimeSeries!$G$2:$G$721,Band_TimeSeries!$A$2:$A$721,1977,Band_TimeSeries!$B$2:$B$721,7) -> -0.027535794 | D16: =B16-C16 -> 0.071346063 | E16: neutral
A17: 1979 | B17: =SUMIFS(Band_TimeSeries!$G$2:$G$721,Band_TimeSeries!$A$2:$A$721,1978,Band_TimeSeries!$B$2:$B$721,3) -> 0.095203389 | C17: =SUMIFS(Band_TimeSeries!$G$2:$G$721,Band_TimeSeries!$A$2:$A$721,1978,Band_TimeSeries!$B$2:$B$721,7) -> -0.13253314 | D17: =B17-C17 -> 0.22773653 | E17: neutral
A18: 1980 | B18: =SUMIFS(Band_TimeSeries!$G$2:$G$721,Band_TimeSeries!$A$2:$A$721,1979,Band_TimeSeries!$B$2:$B$721,3) -> -0.080367673 | C18: =SUMIFS(Band_TimeSeries!$G$2:$G$721,Band_TimeSeries!$A$2:$A$721,1979,Band_TimeSeries!$B$2:$B$721,7) -> 0.018986146 | D18: =B18-C18 -> -0.099353819 | E18: neutral
A19: 1981 | B19: =SUMIFS(Band_TimeSeries!$G$2:$G$721,Band_TimeSeries!$A$2:$A$721,1980,Band_TimeSeries!$B$2:$B$721,3) -> -0.06806182 | C19: =SUMIFS(Band_TimeSeries!$G$2:$G$721,Band_TimeSeries!$A$2:$A$721,1980,Band_TimeSeries!$B$2:$B$721,7) -> 0.065257547 | D19: =B19-C19 -> -0.13331937 | E19: neutral
A20: 1982 | B20: =SUMIFS(Band_TimeSeries!$G$2:$G$721,Band_TimeSeries!$A$2:$A$721,1981,Band_TimeSeries!$B$2:$B$721,3) -> 0.0096457482 | C20: =SUMIFS(Band_TimeSeries!$G$2:$G$721,Band_TimeSeries!$A$2:$A$721,1981,Band_TimeSeries!$B$2:$B$721,7) -> 0.0093935354 | D20: =B20-C20 -> 0.00025221287 | E20: El Nino
A21: 1983 | B21: =SUMIFS(Band_TimeSeries!$G$2:$G$721,Band_TimeSeries!$A$2:$A$721,1982,Band_TimeSeries!$B$2:$B$721,3) -> -0.0065837217 | C21: =SUMIFS(Band_TimeSeries!$G$2:$G$721,Band_TimeSeries!$A$2:$A$721,1982,Band_TimeSeries!$B$2:$B$721,7) -> 0.046866121 | D21: =B21-C21 -> -0.053449842 | E21: neutral
A22: 1984 | B22: =SUMIFS(Band_TimeSeries!$G$2:$G$721,Band_TimeSeries!$A$2:$A$721,1983,Band_TimeSeries!$B$2:$B$721,3) -> 0.12396557 | C22: =SUMIFS(Band_TimeSeries!$G$2:$G$721,Band_TimeSeries!$A$2:$A$721,1983,Band_TimeSeries!$B$2:$B$721,7) -> -0.13540632 | D22: =B22-C22 -> 0.25937188 | E22: La Nina
A23: 1985 | B23: =SUMIFS(Band_TimeSeries!$G$2:$G$721,Band_TimeSeries!$A$2:$A$721,1984,Band_TimeSeries!$B$2:$B$721,3) -> -0.083950339 | C23: =SUMIFS(Band_TimeSeries!$G$2:$G$721,Band_TimeSeries!$A$2:$A$721,1984,Band_TimeSeries!$B$2:$B$721,7) -> 0.032289078 | D23: =B23-C23 -> -0.11623942 | E23: neutral
A24: 1986 | B24: =SUMIFS(Band_TimeSeries!$G$2:$G$721,Band_TimeSeries!$A$2:$A$721,1985,Band_TimeSeries!$B$2:$B$721,3) -> 0.0075342017 | C24: =SUMIFS(Band_TimeSeries!$G$2:$G$721,Band_TimeSeries!$A$2:$A$721,1985,Band_TimeSeries!$B$2:$B$721,7) -> -0.047784709 | D24: =B24-C24 -> 0.055318911 | E24: El Nino
A25: 1987 | B25: =SUMIFS(Band_TimeSeries!$G$2:$G$721,Band_TimeSeries!$A$2:$A$721,1986,Band_TimeSeries!$B$2:$B$721,3) -> -0.097649126 | C25: =SUMIFS(Band_TimeSeries!$G$2:$G$721,Band_TimeSeries!$A$2:$A$721,1986,Band_TimeSeries!$B$2:$B$721,7) -> 0.083520543 | D25: =B25-C25 -> -0.18116967 | E25: El Nino
A26: 1988 | B26: =SUMIFS(Band_TimeSeries!$G$2:$G$721,Band_TimeSeries!$A$2:$A$721,1987,Band_TimeSeries!$B$2:$B$721,3) -> 0.050735303 | C26: =SUMIFS(Band_TimeSeries!$G$2:$G$721,Band_TimeSeries!$A$2:$A$721,1987,Band_TimeSeries!$B$2:$B$721,7) -> -0.034774405 | D26: =B26-C26 -> 0.085509708 | E26: La Nina
A27: 1989 | B27: =SUMIFS(Band_TimeSeries!$G$2:$G$721,Band_TimeSeries!$A$2:$A$721,1988,Band_TimeSeries!$B$2:$B$721,3) -> 0.026359495 | C27: =SUMIFS(Band_TimeSeries!$G$2:$G$721,Band_TimeSeries!$A$2:$A$721,1988,Band_TimeSeries!$B$2:$B$721,7) -> -0.068595764 | D27: =B27-C27 -> 0.094955259 | E27: neutral
A28: 1990 | B28: =SUMIFS(Band_TimeSeries!$G$2:$G$721,Band_TimeSeries!$A$2:$A$721,1989,Band_TimeSeries!$B$2:$B$721,3) -> -0.10000242 | C28: =SUMIFS(Band_TimeSeries!$G$2:$G$721,Band_TimeSeries!$A$2:$A$721,1989,Band_TimeSeries!$B$2:$B$721,7) -> 0.07631456 | D28: =B28-C28 -> -0.17631698 | E28: neutral
A29: 1991 | B29: =SUMIFS(Band_TimeSeries!$G$2:$G$721,Band_TimeSeries!$A$2:$A$721,1990,Band_TimeSeries!$B$2:$B$721,3) -> 0.0048959332 | C29: =SUMIFS(Band_TimeSeries!$G$2:$G$721,Band_TimeSeries!$A$2:$A$721,1990,Band_TimeSeries!$B$2:$B$721,7) -> 0.02259104 | D29: =B29-C29 -> -0.017695107 | E29: El Nino
A30: 1992 | B30: =SUMIFS(Band_TimeSeries!$G$2:$G$721,Band_TimeSeries!$A$2:$A$721,1991,Band_TimeSeries!$B$2:$B$721,3) -> -0.0056281083 | C30: =SUMIFS(Band_TimeSeries!$G$2:$G$721,Band_TimeSeries!$A$2:$A$721,1991,Band_TimeSeries!$B$2:$B$721,7) -> 0.05710119 | D30: =B30-C30 -> -0.062729298 | E30: neutral
A31: 1993 | B31: =SUMIFS(Band_TimeSeries!$G$2:$G$721,Band_TimeSeries!$A$2:$A$721,1992,Band_TimeSeries!$B$2:$B$721,3) -> 0.094457556 | C31: =SUMIFS(Band_TimeSeries!$G$2:$G$721,Band_TimeSeries!$A$2:$A$721,1992,Band_TimeSeries!$B$2:$B$721,7) -> -0.050897454 | D31: =B31-C31 -> 0.14535501 | E31: neutral
A32: 1994 | B32: =SUMIFS(Band_TimeSeries!$G$2:$G$721,Band_TimeSeries!$A$2:$A$721,1993,Band_TimeSeries!$B$2:$B$721,3) -> 0.023633497 | C32: =SUMIFS(Band_TimeSeries!$G$2:$G$721,Band_TimeSeries!$A$2:$A$721,1993,Band_TimeSeries!$B$2:$B$721,7) -> -0.0079579569 | D32: =B32-C32 -> 0.031591453 | E32: El Nino
A33: 1995 | B33: =SUMIFS(Band_TimeSeries!$G$2:$G$721,Band_TimeSeries!$A$2:$A$721,1994,Band_TimeSeries!$B$2:$B$721,3) -> 0.063512436 | C33: =SUMIFS(Band_TimeSeries!$G$2:$G$721,Band_TimeSeries!$A$2:$A$721,1994,Band_TimeSeries!$B$2:$B$721,7) -> -0.059929251 | D33: =B33-C33 -> 0.12344169 | E33: neutral
A34: 1996 | B34: =SUMIFS(Band_TimeSeries!$G$2:$G$721,Band_TimeSeries!$A$2:$A$721,1995,Band_TimeSeries!$B$2:$B$721,3) -> 0.051546636 | C34: =SUMIFS(Band_TimeSeries!$G$2:$G$721,Band_TimeSeries!$A$2:$A$721,1995,Band_TimeSeries!$B$2:$B$721,7) -> -0.11483807 | D34: =B34-C34 -> 0.16638471 | E34: La Nina
A35: 1997 | B35: =SUMIFS(Band_TimeSeries!$G$2:$G$721,Band_TimeSeries!$A$2:$A$721,1996,Band_TimeSeries!$B$2:$B$721,3) -> -0.14202963 | C35: =SUMIFS(Band_TimeSeries!$G$2:$G$721,Band_TimeSeries!$A$2:$A$721,1996,Band_TimeSeries!$B$2:$B$721,7) -> 0.10934934 | D35: =B35-C35 -> -0.25137897 | E35: El Nino
A36: 1998 | B36: =SUMIFS(Band_TimeSeries!$G$2:$G$721,Band_TimeSeries!$A$2:$A$721,1997,Band_TimeSeries!$B$2:$B$721,3) -> 0.027297038 | C36: =SUMIFS(Band_TimeSeries!$G$2:$G$721,Band_TimeSeries!$A$2:$A$721,1997,Band_TimeSeries!$B$2:$B$721,7) -> 0.036953866 | D36: =B36-C36 -> -0.0096568282 | E36: La Nina
A37: 1999 | B37: =SUMIFS(Band_TimeSeries!$G$2:$G$721,Band_TimeSeries!$A$2:$A$721,1998,Band_TimeSeries!$B$2:$B$721,3) -> 0.18400514 | C37: =SUMIFS(Band_TimeSeries!$G$2:$G$721,Band_TimeSeries!$A$2:$A$721,1998,Band_TimeSeries!$B$2:$B$721,7) -> -0.20794991 | D37: =B37-C37 -> 0.39195504 | E37: La Nina
A38: 2000 | B38: =SUMIFS(Band_TimeSeries!$G$2:$G$721,Band_TimeSeries!$A$2:$A$721,1999,Band_TimeSeries!$B$2:$B$721,3) -> -0.093010834 | C38: =SUMIFS(Band_TimeSeries!$G$2:$G$721,Band_TimeSeries!$A$2:$A$721,1999,Band_TimeSeries!$B$2:$B$721,7) -> -0.020360839 | D38: =B38-C38 -> -0.072649995 | E38: neutral
A39: 2001 | B39: =SUMIFS(Band_TimeSeries!$G$2:$G$721,Band_TimeSeries!$A$2:$A$721,2000,Band_TimeSeries!$B$2:$B$721,3) -> -0.15606104 | C39: =SUMIFS(Band_TimeSeries!$G$2:$G$721,Band_TimeSeries!$A$2:$A$721,2000,Band_TimeSeries!$B$2:$B$721,7) -> 0.11499118 | D39: =B39-C39 -> -0.27105222 | E39: neutral
A40: 2002 | B40: =SUMIFS(Band_TimeSeries!$G$2:$G$721,Band_TimeSeries!$A$2:$A$721,2001,Band_TimeSeries!$B$2:$B$721,3) -> -0.019356685 | C40: =SUMIFS(Band_TimeSeries!$G$2:$G$721,Band_TimeSeries!$A$2:$A$721,2001,Band_TimeSeries!$B$2:$B$721,7) -> 0.027509002 | D40: =B40-C40 -> -0.046865686 | E40: El Nino
...

Sheet Key_Stats
A1: Key chain correlations (clean data, n = 59, 1964-2022)
A3: Relationship | B3: r | C3: P | D3: Note
A4: A2 -> SLP_R2 (Y0 May) | B4: 0.38 | C4: 0.003 | D4: NH ridge, boreal late spring; robust channel
A5: A2 -> SLP_R2+R5 (Y0 May) | B5: 0.36 | C5: 0.005 | D5: combined EPSH
A6: A2 -> SLP_R2+R5 (Y-1 Dec) | B6: 0.41 | C6: 0.001 | D6: SH-led; most robust link (survives drop-3)
A7: A2 -> SLP_R5 (Y0 May) | B7: 0.23 | C7: 0.076 | D7: weak in May; R5 peaks in Y-1 Nov-Dec
A8: A2 -> U_R1a (Y0 Jun) | B8: -0.3 | C8: 0.021 | D8: equatorial zonal wind
A9: A2 -> NINO3 (Y0 SON) | B9: -0.31 | C9: 0.016 | D9: ocean endpoint, autumn
A10: A2 -> NINO3 (Y0 DJF) | B10: -0.33 | C10: 0.01 | D10: ocean endpoint, winter
A11: SLP_R2+R5 (May) -> U_R1a (Jun) | B11: -0.47 | C11: 0.0002 | D11: EPSH to wind
A12: U_R1a (Jun) -> SST3a (SON) | B12: 0.63 | C12: 0.0001 | D12: wind to ocean (Bjerknes)
A13: A2 vs prior-winter NINO3 | B13: 0.64 | C13: 0.0001 | D13: phase hand-off; not amplitude coherence
A16: Significance by phase-randomized Monte Carlo (5000 surrogates): effective DOF ~ 42-55;
A17: empirical 95% threshold |r| ~ 0.27-0.30; SLP field significance p = 0.009.
A18: These use external SLP / wind / SST data and are listed for reference (not recomputed in this workbook).

Sheet Corrupted_vs_Clean
A1: What the correction changed
A3: Quantity | B3: Corrupted (old) | C3: Clean (corrected) | D3: Cause / note
A4: 0.5-1 yr band sigma (ms) | B4: 0.173 | C4: 0.064 | D4: Sa/Ssa harmonics not removed -> seasonal leakage (x2.7)
A5: A2 range (ms) | B5: -0.61 to +0.71 | C5: -0.26 to +0.41 | D5: follows directly from the inflated band
A6: A2 for 1997 (ms) | B6: -0.61 | C6: -0.25 | D6: no longer the record extreme (2001 is more negative)
A7: A2 -> SLP_R2+R5 (May) | B7: +0.40 (P=0.0016) | C7: +0.36 (P=0.005) | D7: modest reduction; still significant
A8: A2 -> NINO3 (DJF) | B8: -0.21 (P=0.12, ns) | C8: -0.33 (P=0.010) | D8: now significant after correction
A9: Mediation proportion | B9: 93.8% | C9: ~55% | D9: old total effect was corrupted-small; now substantial partial
A10: Prediction lead framing | B10: 10 to 14 months | C10: 10 months (SST 14-17) | D10: 10 mo to EPSH; SST response later
A11: Dominant period | B11: ~9.6 months | C11: ~9-10 months | D11: spectral peak, not relied upon for significance
A13: The uploaded LOD_5bands_timeseries.xlsx contains the corrupted 0.5-1 yr band (sigma 0.173) and should not be used.
